<?xml version="1.0" encoding="utf-8"?>
<robot xmlns:xacro="http://www.ros.org/wiki/xacro" name="robot">
  <!-- 
  This URDF was automatically created by SolidWorks to URDF Exporter! Originally created by Stephen
  Brawner (brawner@gmail.com) 
     Commit Version: 1.6.0-4-g7f85cfe  Build Version: 1.6.7995.38578
     For more information, please see http://wiki.ros.org/sw_urdf_exporter 
  -->
  <link name="base_link">
    <visual>
      <origin xyz="0 0 0" rpy="0 0 0" />
      <geometry>
        <mesh filename="package://addverb_cobot_description/meshes/base_link.STL" />
      </geometry>
      <material name="">
        <color rgba="0.75294 0.75294 0.75294 1" />
      </material>
    </visual>
    <collision>
      <origin xyz="0 0 0" rpy="0 0 0" />
      <geometry>
        <mesh filename="package://addverb_cobot_description/meshes/base_link.STL" />
      </geometry>
    </collision>
  </link>
  <link name="link1">
    <inertial>
      <origin xyz="-0.012435 -2.5345E-05 0.28172" rpy="0 0 0" />
      <mass value="5.0617" />
      <inertia ixx="0.011934" ixy="-4.2772E-06" ixz="0.0016521" iyy="0.011427" iyz="3.2849E-06"
        izz="0.0091785" />
    </inertial>
    <visual>
      <origin xyz="0 0 0" rpy="0 0 0" />
      <geometry>
        <mesh filename="package://addverb_cobot_description/meshes/link1.STL" />
      </geometry>
      <material name="">
        <color rgba="0.75294 0.75294 0.75294 1" />
      </material>
    </visual>
    <collision>
      <origin xyz="0 0 0" rpy="0 0 0" />
      <geometry>
        <mesh filename="package://addverb_cobot_description/meshes/link1.STL" />
      </geometry>
    </collision>
  </link>
  <joint name="joint1" type="revolute">
    <origin xyz="0 0 0" rpy="0 0 0" />
    <parent link="base_link" />
    <child link="link1" />
    <axis xyz="0 0 1" />
    <limit lower="-${pi}" upper="${pi}" effort="150" velocity="3" />
  </joint>
  <link name="link2">
    <inertial>
      <origin xyz="-0.10679 3.7919E-06 0.15236" rpy="0 0 0" />
      <mass value="1.2353" />
      <inertia ixx="0.0057954" ixy="3.2114E-08" ixz="3.5658E-06" iyy="0.0048706" iyz="-6.4438E-07"
        izz="0.0016259" />
    </inertial>
    <visual>
      <origin xyz="0 0 0" rpy="0 0 0" />
      <geometry>
        <mesh filename="package://addverb_cobot_description/meshes/link2.STL" />
      </geometry>
      <material name="">
        <color rgba="0.75294 0.75294 0.75294 1" />
      </material>
    </visual>
    <collision>
      <origin xyz="0 0 0" rpy="0 0 0" />
      <geometry>
        <mesh filename="package://addverb_cobot_description/meshes/link2.STL" />
      </geometry>
    </collision>
  </link>
  <joint name="joint2" type="revolute">
    <origin xyz="0 0 0.346" rpy="0 0 0" />
    <parent link="link1" />
    <child link="link2" />
    <axis xyz="-1 0 0" />
    <limit lower="-0.75" upper="2.05" effort="150" velocity="1" />
  </joint>
  <link name="link3">
    <inertial>
      <origin xyz="-0.017248 0.035025 -2.2087E-05" rpy="0 0 0" />
      <mass value="3.5577" />
      <inertia ixx="0.0066247" ixy="-0.00095453" ixz="1.793E-06" iyy="0.0050017" iyz="1.7882E-06"
        izz="0.0060636" />
    </inertial>
    <visual>
      <origin xyz="0 0 0" rpy="0 0 0" />
      <geometry>
        <mesh filename="package://addverb_cobot_description/meshes/link3.STL" />
      </geometry>
      <material name="">
        <color rgba="0.75294 0.75294 0.75294 1" />
      </material>
    </visual>
    <collision>
      <origin xyz="0 0 0" rpy="0 0 0" />
      <geometry>
        <mesh filename="package://addverb_cobot_description/meshes/link3.STL" />
      </geometry>
    </collision>
  </link>
  <joint name="joint3" type="revolute">
    <origin xyz="0 0 0.305" rpy="0 0 0" />
    <parent link="link2" />
    <child link="link3" />
    <axis xyz="1 0 0" />
    <limit lower="-1" upper="1" effort="150" velocity="5" />
  </joint>
  <link name="link4">
    <inertial>
      <origin xyz="-0.047999 -0.10939 4.4809E-05" rpy="0 0 0" />
      <mass value="1.31" />
      <inertia ixx="0.0014749" ixy="0.00050231" ixz="1.7564E-06" iyy="0.0016894" iyz="-1.9993E-06"
        izz="0.0017778" />
    </inertial>
    <visual>
      <origin xyz="0 0 0" rpy="0 0 0" />
      <geometry>
        <mesh filename="package://addverb_cobot_description/meshes/link4.STL" />
      </geometry>
      <material name="">
        <color rgba="0.75294 0.75294 0.75294 1" />
      </material>
    </visual>
    <collision>
      <origin xyz="0 0 0" rpy="0 0 0" />
      <geometry>
        <mesh filename="package://addverb_cobot_description/meshes/link4.STL" />
      </geometry>
    </collision>
  </link>
  <joint name="joint4" type="revolute">
    <origin xyz="-0.0009127 0.36813 0" rpy="0 0 0" />
    <parent link="link3" />
    <child link="link4" />
    <axis xyz="0 1 0" />
    <limit lower="-${pi}" upper="${pi}" effort="80" velocity="1" />
  </joint>
  <link name="link5">
    <inertial>
      <origin xyz="-0.0015193 -0.0027725 -0.044032" rpy="0 0 0" />
      <mass value="1.1965" />
      <inertia ixx="0.0010777" ixy="-3.7989E-05" ixz="2.9305E-05" iyy="0.0010311" iyz="4.9507E-05"
        izz="0.0013412" />
    </inertial>
    <visual>
      <origin xyz="0 0 0" rpy="0 0 0" />
      <geometry>
        <mesh filename="package://addverb_cobot_description/meshes/link5.STL" />
      </geometry>
      <material name="">
        <color rgba="0.75294 0.75294 0.75294 1" />
      </material>
    </visual>
    <collision>
      <origin xyz="0 0 0" rpy="0 0 0" />
      <geometry>
        <mesh filename="package://addverb_cobot_description/meshes/link5.STL" />
      </geometry>
    </collision>
  </link>
  <joint name="joint5" type="revolute">
    <origin xyz="0 0 0" rpy="0 0 0" />
    <parent link="link4" />
    <child link="link5" />
    <axis xyz="0.5 0.86603 0" />
    <limit lower="-${pi}" upper="${pi}" effort="80" velocity="1" />
  </joint>
  <link name="end-effector" />

  <joint name="joint6" type="revolute">
    <origin xyz="0 0 -0.0975" rpy="0 0 0" />
    <parent link="link5" />
    <child link="end-effector" />
    <axis xyz="0 0 -1" />
    <limit lower="-${pi}" upper="${pi}" effort="80" velocity="1" />
  </joint>
</robot>